Unhandled exception in thread started by <function wrapper at 0x110bf68c0>
Performing system checks...

Traceback (most recent call last):
  File "/Library/Python/2.7/site-packages/django/utils/autoreload.py", line 229, in wrapper
    fn(*args, **kwargs)
  File "/Library/Python/2.7/site-packages/django/core/management/commands/runserver.py", line 114, in inner_run
    self.validate(display_num_errors=True)
  File "/Library/Python/2.7/site-packages/django/core/management/base.py", line 469, in validate
    return self.check(app_configs=app_configs, display_num_errors=display_num_errors)
  File "/Library/Python/2.7/site-packages/django/core/management/base.py", line 482, in check
    include_deployment_checks=include_deployment_checks,
  File "/Library/Python/2.7/site-packages/django/core/checks/registry.py", line 72, in run_checks
    new_errors = check(app_configs=app_configs)
  File "/Library/Python/2.7/site-packages/django/core/checks/model_checks.py", line 28, in check_all_models
    errors.extend(model.check(**kwargs))
  File "/Library/Python/2.7/site-packages/django/db/models/base.py", line 1205, in check
    errors.extend(cls._check_fields(**kwargs))
  File "/Library/Python/2.7/site-packages/django/db/models/base.py", line 1282, in _check_fields
    errors.extend(field.check(**kwargs))
  File "/Library/Python/2.7/site-packages/django/db/models/fields/__init__.py", line 934, in check
    errors = super(AutoField, self).check(**kwargs)
  File "/Library/Python/2.7/site-packages/django/db/models/fields/__init__.py", line 207, in check
    errors.extend(self._check_backend_specific_checks(**kwargs))
  File "/Library/Python/2.7/site-packages/django/db/models/fields/__init__.py", line 306, in _check_backend_specific_checks
    return connection.validation.check_field(self, **kwargs)
  File "/Library/Python/2.7/site-packages/django/db/backends/mysql/validation.py", line 18, in check_field
    field_type = field.db_type(connection)
  File "/Library/Python/2.7/site-packages/django/db/models/fields/__init__.py", line 614, in db_type
    return connection.data_types[self.get_internal_type()] % data
  File "/Library/Python/2.7/site-packages/django/db/__init__.py", line 36, in __getattr__
    return getattr(connections[DEFAULT_DB_ALIAS], item)
  File "/Library/Python/2.7/site-packages/django/utils/functional.py", line 59, in __get__
    res = instance.__dict__[self.name] = self.func(instance)
  File "/Library/Python/2.7/site-packages/django/db/backends/mysql/base.py", line 196, in data_types
    if self.features.supports_microsecond_precision:
  File "/Library/Python/2.7/site-packages/django/utils/functional.py", line 59, in __get__
    res = instance.__dict__[self.name] = self.func(instance)
  File "/Library/Python/2.7/site-packages/django/db/backends/mysql/features.py", line 52, in supports_microsecond_precision
    return self.connection.mysql_version >= (5, 6, 4) and Database.version_info >= (1, 2, 5)
  File "/Library/Python/2.7/site-packages/django/utils/functional.py", line 59, in __get__
    res = instance.__dict__[self.name] = self.func(instance)
  File "/Library/Python/2.7/site-packages/django/db/backends/mysql/base.py", line 371, in mysql_version
    with self.temporary_connection():
  File "/System/Library/Frameworks/Python.framework/Versions/2.7/lib/python2.7/contextlib.py", line 17, in __enter__
    return self.gen.next()
  File "/Library/Python/2.7/site-packages/django/db/backends/base/base.py", line 462, in temporary_connection
    cursor = self.cursor()
  File "/Library/Python/2.7/site-packages/django/db/backends/base/base.py", line 162, in cursor
    cursor = self.make_debug_cursor(self._cursor())
  File "/Library/Python/2.7/site-packages/django/db/backends/base/base.py", line 135, in _cursor
    self.ensure_connection()
  File "/Library/Python/2.7/site-packages/django/db/backends/base/base.py", line 130, in ensure_connection
    self.connect()
  File "/Library/Python/2.7/site-packages/django/db/utils.py", line 98, in __exit__
    six.reraise(dj_exc_type, dj_exc_value, traceback)
  File "/Library/Python/2.7/site-packages/django/db/backends/base/base.py", line 130, in ensure_connection
    self.connect()
  File "/Library/Python/2.7/site-packages/django/db/backends/base/base.py", line 119, in connect
    self.connection = self.get_new_connection(conn_params)
  File "/Library/Python/2.7/site-packages/django/db/backends/mysql/base.py", line 276, in get_new_connection
    conn = Database.connect(**conn_params)
  File "/Library/Python/2.7/site-packages/MySQL_python-1.2.4-py2.7-macosx-10.11-intel.egg/MySQLdb/__init__.py", line 81, in Connect
  File "/Library/Python/2.7/site-packages/MySQL_python-1.2.4-py2.7-macosx-10.11-intel.egg/MySQLdb/connections.py", line 193, in __init__
django.db.utils.OperationalError: (1044, "Access denied for user ''@'localhost' to database '/access_record/my.cnf'")
